Found ulimit of 10240 and failed to automatically increase with error current limit exceeds maximum limit. This can cause fd limit errors like `OSError: [Errno 24] Too many open files`. Consider increasing with ulimit -n
Traceback (most recent call last):
  File "/home/aimotion_api/anaconda3/envs/seraphim_vllm_env/lib/python3.10/site-packages/huggingface_hub/utils/_http.py", line 409, in hf_raise_for_status
    response.raise_for_status()
  File "/home/aimotion_api/anaconda3/envs/seraphim_vllm_env/lib/python3.10/site-packages/requests/models.py", line 1024, in raise_for_status
    raise HTTPError(http_error_msg, response=self)
requests.exceptions.HTTPError: 403 Client Error: Forbidden for url: https://huggingface.co/mistralai/Mistral-7B-Instruct-v0.1/resolve/main/config.json

The above exception was the direct cause of the following exception:

Traceback (most recent call last):
  File "/home/aimotion_api/anaconda3/envs/seraphim_vllm_env/lib/python3.10/site-packages/transformers/utils/hub.py", line 424, in cached_files
    hf_hub_download(
  File "/home/aimotion_api/anaconda3/envs/seraphim_vllm_env/lib/python3.10/site-packages/huggingface_hub/utils/_validators.py", line 114, in _inner_fn
    return fn(*args, **kwargs)
  File "/home/aimotion_api/anaconda3/envs/seraphim_vllm_env/lib/python3.10/site-packages/huggingface_hub/file_download.py", line 1008, in hf_hub_download
    return _hf_hub_download_to_cache_dir(
  File "/home/aimotion_api/anaconda3/envs/seraphim_vllm_env/lib/python3.10/site-packages/huggingface_hub/file_download.py", line 1115, in _hf_hub_download_to_cache_dir
    _raise_on_head_call_error(head_call_error, force_download, local_files_only)
  File "/home/aimotion_api/anaconda3/envs/seraphim_vllm_env/lib/python3.10/site-packages/huggingface_hub/file_download.py", line 1643, in _raise_on_head_call_error
    raise head_call_error
  File "/home/aimotion_api/anaconda3/envs/seraphim_vllm_env/lib/python3.10/site-packages/huggingface_hub/file_download.py", line 1531, in _get_metadata_or_catch_error
    metadata = get_hf_file_metadata(
  File "/home/aimotion_api/anaconda3/envs/seraphim_vllm_env/lib/python3.10/site-packages/huggingface_hub/utils/_validators.py", line 114, in _inner_fn
    return fn(*args, **kwargs)
  File "/home/aimotion_api/anaconda3/envs/seraphim_vllm_env/lib/python3.10/site-packages/huggingface_hub/file_download.py", line 1448, in get_hf_file_metadata
    r = _request_wrapper(
  File "/home/aimotion_api/anaconda3/envs/seraphim_vllm_env/lib/python3.10/site-packages/huggingface_hub/file_download.py", line 286, in _request_wrapper
    response = _request_wrapper(
  File "/home/aimotion_api/anaconda3/envs/seraphim_vllm_env/lib/python3.10/site-packages/huggingface_hub/file_download.py", line 310, in _request_wrapper
    hf_raise_for_status(response)
  File "/home/aimotion_api/anaconda3/envs/seraphim_vllm_env/lib/python3.10/site-packages/huggingface_hub/utils/_http.py", line 426, in hf_raise_for_status
    raise _format(GatedRepoError, message, response) from e
huggingface_hub.errors.GatedRepoError: 403 Client Error. (Request ID: Root=1-681f23fa-57c9199632bb3a0424b40703;eeb015a7-deb6-49c4-ad9b-c99a937affaa)

Cannot access gated repo for url https://huggingface.co/mistralai/Mistral-7B-Instruct-v0.1/resolve/main/config.json.
Access to model mistralai/Mistral-7B-Instruct-v0.1 is restricted and you are not in the authorized list. Visit https://huggingface.co/mistralai/Mistral-7B-Instruct-v0.1 to ask for access.

The above exception was the direct cause of the following exception:

Traceback (most recent call last):
  File "/home/aimotion_api/anaconda3/envs/seraphim_vllm_env/bin/vllm", line 8, in <module>
    sys.exit(main())
  File "/home/aimotion_api/anaconda3/envs/seraphim_vllm_env/lib/python3.10/site-packages/vllm/entrypoints/cli/main.py", line 53, in main
    args.dispatch_function(args)
  File "/home/aimotion_api/anaconda3/envs/seraphim_vllm_env/lib/python3.10/site-packages/vllm/entrypoints/cli/serve.py", line 27, in cmd
    uvloop.run(run_server(args))
  File "/home/aimotion_api/anaconda3/envs/seraphim_vllm_env/lib/python3.10/site-packages/uvloop/__init__.py", line 82, in run
    return loop.run_until_complete(wrapper())
  File "uvloop/loop.pyx", line 1518, in uvloop.loop.Loop.run_until_complete
  File "/home/aimotion_api/anaconda3/envs/seraphim_vllm_env/lib/python3.10/site-packages/uvloop/__init__.py", line 61, in wrapper
    return await main
  File "/home/aimotion_api/anaconda3/envs/seraphim_vllm_env/lib/python3.10/site-packages/vllm/entrypoints/openai/api_server.py", line 1078, in run_server
    async with build_async_engine_client(args) as engine_client:
  File "/home/aimotion_api/anaconda3/envs/seraphim_vllm_env/lib/python3.10/contextlib.py", line 199, in __aenter__
    return await anext(self.gen)
  File "/home/aimotion_api/anaconda3/envs/seraphim_vllm_env/lib/python3.10/site-packages/vllm/entrypoints/openai/api_server.py", line 146, in build_async_engine_client
    async with build_async_engine_client_from_engine_args(
  File "/home/aimotion_api/anaconda3/envs/seraphim_vllm_env/lib/python3.10/contextlib.py", line 199, in __aenter__
    return await anext(self.gen)
  File "/home/aimotion_api/anaconda3/envs/seraphim_vllm_env/lib/python3.10/site-packages/vllm/entrypoints/openai/api_server.py", line 166, in build_async_engine_client_from_engine_args
    vllm_config = engine_args.create_engine_config(usage_context=usage_context)
  File "/home/aimotion_api/anaconda3/envs/seraphim_vllm_env/lib/python3.10/site-packages/vllm/engine/arg_utils.py", line 1099, in create_engine_config
    model_config = self.create_model_config()
  File "/home/aimotion_api/anaconda3/envs/seraphim_vllm_env/lib/python3.10/site-packages/vllm/engine/arg_utils.py", line 987, in create_model_config
    return ModelConfig(
  File "/home/aimotion_api/anaconda3/envs/seraphim_vllm_env/lib/python3.10/site-packages/vllm/config.py", line 451, in __init__
    hf_config = get_config(self.hf_config_path or self.model,
  File "/home/aimotion_api/anaconda3/envs/seraphim_vllm_env/lib/python3.10/site-packages/vllm/transformers_utils/config.py", line 303, in get_config
    config_dict, _ = PretrainedConfig.get_config_dict(
  File "/home/aimotion_api/anaconda3/envs/seraphim_vllm_env/lib/python3.10/site-packages/transformers/configuration_utils.py", line 590, in get_config_dict
    config_dict, kwargs = cls._get_config_dict(pretrained_model_name_or_path, **kwargs)
  File "/home/aimotion_api/anaconda3/envs/seraphim_vllm_env/lib/python3.10/site-packages/transformers/configuration_utils.py", line 649, in _get_config_dict
    resolved_config_file = cached_file(
  File "/home/aimotion_api/anaconda3/envs/seraphim_vllm_env/lib/python3.10/site-packages/transformers/utils/hub.py", line 266, in cached_file
    file = cached_files(path_or_repo_id=path_or_repo_id, filenames=[filename], **kwargs)
  File "/home/aimotion_api/anaconda3/envs/seraphim_vllm_env/lib/python3.10/site-packages/transformers/utils/hub.py", line 481, in cached_files
    raise OSError(
OSError: You are trying to access a gated repo.
Make sure to have access to it at https://huggingface.co/mistralai/Mistral-7B-Instruct-v0.1.
403 Client Error. (Request ID: Root=1-681f23fa-57c9199632bb3a0424b40703;eeb015a7-deb6-49c4-ad9b-c99a937affaa)

Cannot access gated repo for url https://huggingface.co/mistralai/Mistral-7B-Instruct-v0.1/resolve/main/config.json.
Access to model mistralai/Mistral-7B-Instruct-v0.1 is restricted and you are not in the authorized list. Visit https://huggingface.co/mistralai/Mistral-7B-Instruct-v0.1 to ask for access.
